Workbook

Sheet Dashboard
A1: Azure DevOps / AKS Deployment Project — Dashboard
A2: Last Updated: March 06, 2026
A4: Phase | B4: Owner | C4: Priority | D4: % Complete | E4: Status | F4: Start Date | G4: End Date | H4: Open Tasks | I4: Blocked | J4: Notes
A5: Build | B5: TBD | C5: P2 - High | D5: =IFERROR(AVERAGEIF('Project Overview'!$B$5:$B$100,A5,'Project Overview'!$G$5:$G$100),0) -> 0 | E5: =IF('Project Overview'!$G$5:$G$100="","",IF(AVERAGEIF('Project Overview'!$B$5:$B$100,A5,'Project Overview'!$G$5:$G$100)=1,"Complete",IF(AVERAGEIF('Project Overview'!$B$5:$B$100,A5,'Project Overview'!$G$5:$G$100)>0,"In Progress","Not Started"))) -> Not Started | F5: =IFERROR(_xludf.MINIFS('Project Overview'!$H$5:$H$100,'Project Overview'!$B$5:$B$100,A5),"TBD") -> TBD | G5: =IFERROR(_xludf.MAXIFS('Project Overview'!$I$5:$I$100,'Project Overview'!$B$5:$B$100,A5),"TBD") -> TBD | H5: =COUNTIFS('Project Overview'!$B$5:$B$100,A5,'Project Overview'!$F$5:$F$100,"<>Complete") -> 14 | I5: =COUNTIFS('Project Overview'!$B$5:$B$100,A5,'Project Overview'!$F$5:$F$100,"Blocked") -> 0
A6: Application | B6: TBD | C6: P2 - High | D6: =IFERROR(AVERAGEIF('Project Overview'!$B$5:$B$100,A6,'Project Overview'!$G$5:$G$100),0) -> 0 | E6: =IF('Project Overview'!$G$5:$G$100="","",IF(AVERAGEIF('Project Overview'!$B$5:$B$100,A6,'Project Overview'!$G$5:$G$100)=1,"Complete",IF(AVERAGEIF('Project Overview'!$B$5:$B$100,A6,'Project Overview'!$G$5:$G$100)>0,"In Progress","Not Started"))) -> Not Started | F6: =IFERROR(_xludf.MINIFS('Project Overview'!$H$5:$H$100,'Project Overview'!$B$5:$B$100,A6),"TBD") -> TBD | G6: =IFERROR(_xludf.MAXIFS('Project Overview'!$I$5:$I$100,'Project Overview'!$B$5:$B$100,A6),"TBD") -> TBD | H6: =COUNTIFS('Project Overview'!$B$5:$B$100,A6,'Project Overview'!$F$5:$F$100,"<>Complete") -> 10 | I6: =COUNTIFS('Project Overview'!$B$5:$B$100,A6,'Project Overview'!$F$5:$F$100,"Blocked") -> 0
A7: Security | B7: TBD | C7: P1 - Critical | D7: =IFERROR(AVERAGEIF('Project Overview'!$B$5:$B$100,A7,'Project Overview'!$G$5:$G$100),0) -> 0 | E7: =IF('Project Overview'!$G$5:$G$100="","",IF(AVERAGEIF('Project Overview'!$B$5:$B$100,A7,'Project Overview'!$G$5:$G$100)=1,"Complete",IF(AVERAGEIF('Project Overview'!$B$5:$B$100,A7,'Project Overview'!$G$5:$G$100)>0,"In Progress","Not Started"))) -> Not Started | F7: =IFERROR(_xludf.MINIFS('Project Overview'!$H$5:$H$100,'Project Overview'!$B$5:$B$100,A7),"TBD") -> TBD | G7: =IFERROR(_xludf.MAXIFS('Project Overview'!$I$5:$I$100,'Project Overview'!$B$5:$B$100,A7),"TBD") -> TBD | H7: =COUNTIFS('Project Overview'!$B$5:$B$100,A7,'Project Overview'!$F$5:$F$100,"<>Complete") -> 10 | I7: =COUNTIFS('Project Overview'!$B$5:$B$100,A7,'Project Overview'!$F$5:$F$100,"Blocked") -> 0
A8: Operationalisation | B8: TBD | C8: P3 - Medium | D8: =IFERROR(AVERAGEIF('Project Overview'!$B$5:$B$100,A8,'Project Overview'!$G$5:$G$100),0) -> 0 | E8: =IF('Project Overview'!$G$5:$G$100="","",IF(AVERAGEIF('Project Overview'!$B$5:$B$100,A8,'Project Overview'!$G$5:$G$100)=1,"Complete",IF(AVERAGEIF('Project Overview'!$B$5:$B$100,A8,'Project Overview'!$G$5:$G$100)>0,"In Progress","Not Started"))) -> Not Started | F8: =IFERROR(_xludf.MINIFS('Project Overview'!$H$5:$H$100,'Project Overview'!$B$5:$B$100,A8),"TBD") -> TBD | G8: =IFERROR(_xludf.MAXIFS('Project Overview'!$I$5:$I$100,'Project Overview'!$B$5:$B$100,A8),"TBD") -> TBD | H8: =COUNTIFS('Project Overview'!$B$5:$B$100,A8,'Project Overview'!$F$5:$F$100,"<>Complete") -> 10 | I8: =COUNTIFS('Project Overview'!$B$5:$B$100,A8,'Project Overview'!$F$5:$F$100,"Blocked") -> 0
A9: Compliance | B9: TBD | C9: P1 - Critical | D9: =IFERROR(AVERAGEIF('Project Overview'!$B$5:$B$100,A9,'Project Overview'!$G$5:$G$100),0) -> 0 | E9: =IF('Project Overview'!$G$5:$G$100="","",IF(AVERAGEIF('Project Overview'!$B$5:$B$100,A9,'Project Overview'!$G$5:$G$100)=1,"Complete",IF(AVERAGEIF('Project Overview'!$B$5:$B$100,A9,'Project Overview'!$G$5:$G$100)>0,"In Progress","Not Started"))) -> Not Started | F9: =IFERROR(_xludf.MINIFS('Project Overview'!$H$5:$H$100,'Project Overview'!$B$5:$B$100,A9),"TBD") -> TBD | G9: =IFERROR(_xludf.MAXIFS('Project Overview'!$I$5:$I$100,'Project Overview'!$B$5:$B$100,A9),"TBD") -> TBD | H9: =COUNTIFS('Project Overview'!$B$5:$B$100,A9,'Project Overview'!$F$5:$F$100,"<>Complete") -> 7 | I9: =COUNTIFS('Project Overview'!$B$5:$B$100,A9,'Project Overview'!$F$5:$F$100,"Blocked") -> 0
A10: Documentation | B10: TBD | C10: P3 - Medium | D10: =IFERROR(AVERAGEIF('Project Overview'!$B$5:$B$100,A10,'Project Overview'!$G$5:$G$100),0) -> 0 | E10: =IF('Project Overview'!$G$5:$G$100="","",IF(AVERAGEIF('Project Overview'!$B$5:$B$100,A10,'Project Overview'!$G$5:$G$100)=1,"Complete",IF(AVERAGEIF('Project Overview'!$B$5:$B$100,A10,'Project Overview'!$G$5:$G$100)>0,"In Progress","Not Started"))) -> Not Started | F10: =IFERROR(_xludf.MINIFS('Project Overview'!$H$5:$H$100,'Project Overview'!$B$5:$B$100,A10),"TBD") -> TBD | G10: =IFERROR(_xludf.MAXIFS('Project Overview'!$I$5:$I$100,'Project Overview'!$B$5:$B$100,A10),"TBD") -> TBD | H10: =COUNTIFS('Project Overview'!$B$5:$B$100,A10,'Project Overview'!$F$5:$F$100,"<>Complete") -> 10 | I10: =COUNTIFS('Project Overview'!$B$5:$B$100,A10,'Project Overview'!$F$5:$F$100,"Blocked") -> 0
A13: PHASE LEGEND | D13: STATUS LEGEND | G13: PRIORITY LEGEND
B14: Build | E14: Not Started | H14: P1 - Critical
B15: Application | E15: In Progress | H15: P2 - High
B16: Security | E16: Complete | H16: P3 - Medium
B17: Operationalisation | E17: Blocked | H17: P4 - Low
B18: Compliance | E18: At Risk
B19: Documentation

Sheet Project Overview
A1: Project Overview — AWS Health Notification Remediation
A2: Update Status and % Complete weekly. Use dropdowns for Phase, Owner, Priority and Status.
A4: # | B4: Phase | C4: Task | D4: Assigned To | E4: Priority | F4: Status | G4: % Done | H4: Start | I4: Due | J4: Dependencies | K4: Requested By | L4: Technology | M4: Team | N4: Notes
A5: 1 | B5: Build | C5: Azure DevOps Organisation & Project setup | D5: Cloud Engineer | E5: P1 - Critical | F5: Not Started | G5: 0 | H5: 2025-03-01 | I5: 2025-03-07 | N5: Create ADO org, project, repos and branch policies
A6: 2 | B6: Build | C6: Azure Container Registry (ACR) provisioning | D6: Cloud Engineer | E6: P1 - Critical | F6: Not Started | G6: 0 | H6: 2025-03-05 | I6: 2025-03-10 | J6: Task 1 | N6: Enable geo-replication and private endpoint
A7: 3 | B7: Build | C7: AKS cluster provisioning — system node pool | D7: Cloud Engineer | E7: P1 - Critical | F7: Not Started | G7: 0 | H7: 2025-03-08 | I7: 2025-03-20 | J7: Task 2 | N7: RBAC enabled, private cluster, CNI networking
A8: 4 | B8: Build | C8: AKS user node pools — workload sizing | D8: Cloud Engineer | E8: P2 - High | F8: Not Started | G8: 0 | H8: 2025-03-15 | I8: 2025-03-22 | J8: Task 3 | N8: Separate pools per workload type; autoscale enabled
A9: 5 | B9: Build | C9: Azure Virtual Network (VNet) and subnet design | D9: Cloud Engineer | E9: P1 - Critical | F9: Not Started | G9: 0 | H9: 2025-03-01 | I9: 2025-03-07 | N9: Hub-spoke topology; dedicated AKS subnet
A10: 6 | B10: Build | C10: Azure Firewall — policy and rule collection groups | D10: Security Architect | E10: P1 - Critical | F10: Not Started | G10: 0 | H10: 2025-03-08 | I10: 2025-03-15 | J10: Task 5 | N10: Egress rules for AKS, ACR, Key Vault, ADO agents
A11: 7 | B11: Build | C11: Network Security Groups (NSGs) per subnet | D11: Cloud Engineer | E11: P2 - High | F11: Not Started | G11: 0 | H11: 2025-03-08 | I11: 2025-03-14 | J11: Task 5 | N11: Deny-all default; allow only required ports
A12: 8 | B12: Build | C12: Private Endpoints — ACR, Key Vault, Service Bus | D12: Cloud Engineer | E12: P2 - High | F12: Not Started | G12: 0 | H12: 2025-03-12 | I12: 2025-03-19 | J12: Tasks 5-7 | N12: Disable public access after PE creation
A13: 9 | B13: Build | C13: Azure Key Vault provisioning and access policies | D13: Security Architect | E13: P1 - Critical | F13: Not Started | G13: 0 | H13: 2025-03-08 | I13: 2025-03-14 | J13: Task 5 | N13: Soft-delete, purge protection enabled; RBAC auth mode
A14: 10 | B14: Build | C14: Azure Service Bus namespace and topics | D14: Cloud Engineer | E14: P2 - High | F14: Not Started | G14: 0 | H14: 2025-03-15 | I14: 2025-03-21 | J14: Task 8 | N14: Premium tier for VNet integration; health event routing
A15: 11 | B15: Build | C15: ADO self-hosted agent pool on AKS | D15: Cloud Engineer | E15: P2 - High | F15: Not Started | G15: 0 | H15: 2025-03-20 | I15: 2025-03-27 | J15: Tasks 3,6 | N15: Agents run as pods; access to ACR and Key Vault
A16: 12 | B16: Build | C16: Helm chart development — application workloads | D16: Developer | E16: P2 - High | F16: Not Started | G16: 0 | H16: 2025-03-22 | I16: 2025-04-04 | J16: Tasks 3,9 | N16: Parameterise per environment; secrets from Key Vault
A17: 13 | B17: Build | C17: Infrastructure as Code — Terraform modules | D17: Cloud Engineer | E17: P2 - High | F17: Not Started | G17: 0 | H17: 2025-03-01 | I17: 2025-03-28 | N17: Modules: AKS, ACR, Firewall, VNet, KV, Sentinel
A18: 14 | B18: Build | C18: Terraform remote state — Azure Storage Account | D18: Cloud Engineer | E18: P2 - High | F18: Not Started | G18: 0 | H18: 2025-03-01 | I18: 2025-03-05 | N18: State locking via blob lease; versioning enabled
A19: 15 | B19: Application | C19: ADO Pipeline — CI build and container image publish | D19: Developer | E19: P2 - High | F19: Not Started | G19: 0 | H19: 2025-04-01 | I19: 2025-04-10 | J19: Tasks 2,11 | N19: YAML pipeline; image scanning gate before push to ACR
A20: 16 | B20: Application | C20: ADO Pipeline — CD deploy to AKS via Helm | D20: Developer | E20: P2 - High | F20: Not Started | G20: 0 | H20: 2025-04-05 | I20: 2025-04-14 | J20: Task 15 | N20: Blue-green or rolling; approval gate for prod
A21: 17 | B21: Application | C21: ADO Pipeline — Terraform plan/apply with approval gate | D21: Cloud Engineer | E21: P2 - High | F21: Not Started | G21: 0 | H21: 2025-04-01 | I21: 2025-04-10 | J21: Task 13 | N21: Separate pipelines per environment
A22: 18 | B22: Application | C22: Container image hardening — base image standards | D22: Security Architect | E22: P1 - Critical | F22: Not Started | G22: 0 | H22: 2025-03-25 | I22: 2025-04-04 | J22: Task 2 | N22: Distroless or minimal base; no root user
A23: 19 | B23: Application | C23: Kubernetes manifests — resource limits and requests | D23: Developer | E23: P3 - Medium | F23: Not Started | G23: 0 | H23: 2025-04-01 | I23: 2025-04-10 | J23: Task 12 | N23: Set CPU/memory limits on all containers
A24: 20 | B24: Application | C24: Kubernetes RBAC — service accounts and role bindings | D24: Security Architect | E24: P1 - Critical | F24: Not Started | G24: 0 | H24: 2025-03-22 | I24: 2025-03-28 | J24: Task 3 | N24: Least privilege; no cluster-admin for workloads
A25: 21 | B25: Application | C25: Workload Identity — Azure AD pod identity | D25: Security Architect | E25: P1 - Critical | F25: Not Started | G25: 0 | H25: 2025-03-22 | I25: 2025-03-28 | J25: Tasks 3,9 | N25: Replace service principal secrets with managed identity
A26: 22 | B26: Application | C26: Ingress controller — Application Gateway / NGINX | D26: Cloud Engineer | E26: P2 - High | F26: Not Started | G26: 0 | H26: 2025-04-05 | I26: 2025-04-14 | J26: Tasks 3,7 | N26: TLS termination; WAF policy attached
A27: 23 | B27: Application | C27: Horizontal Pod Autoscaler (HPA) configuration | D27: Developer | E27: P3 - Medium | F27: Not Started | G27: 0 | H27: 2025-04-10 | I27: 2025-04-17 | J27: Task 19 | N27: CPU and memory based scaling per workload
A28: 24 | B28: Application | C28: Multi-environment config — Dev / Non-Prod / Prod | D28: Developer | E28: P2 - High | F28: Not Started | G28: 0 | H28: 2025-04-01 | I28: 2025-04-10 | J28: Task 12 | N28: Separate namespaces or clusters per env
A29: 25 | B29: Security | C29: Azure Entra ID — groups, roles, and RBAC assignments | D29: Security Architect | E29: P1 - Critical | F29: Not Started | G29: 0 | H29: 2025-03-01 | I29: 2025-03-14 | N29: No direct user assignments; use groups only
A30: 26 | B30: Security | C30: Azure Policy — deny non-compliant resource deployments | D30: Compliance Officer | E30: P1 - Critical | F30: Not Started | G30: 0 | H30: 2025-03-15 | I30: 2025-03-28 | J30: Task 25 | N30: Built-in initiatives: CIS, NIST, Protected B
A31: 27 | B31: Security | C31: Microsoft Defender for Cloud — all plans enabled | D31: Security Architect | E31: P1 - Critical | F31: Not Started | G31: 0 | H31: 2025-03-10 | I31: 2025-03-17 | N31: Enable Defender for Containers, Key Vault, DNS, ARM
A32: 28 | B32: Security | C32: Microsoft Defender for Containers — AKS integration | D32: Security Architect | E32: P1 - Critical | F32: Not Started | G32: 0 | H32: 2025-03-17 | I32: 2025-03-24 | J32: Tasks 3,27 | N32: Runtime threat detection; image vulnerability scanning
A33: 29 | B33: Security | C33: Microsoft Sentinel — workspace and data connectors | D33: Security Architect | E33: P1 - Critical | F33: Not Started | G33: 0 | H33: 2025-03-10 | I33: 2025-03-24 | N33: Connect: AAD, Defender, AKS, Firewall, Activity Log
A34: 30 | B34: Security | C34: Sentinel — Analytics rules and MITRE ATT&CK mapping | D34: Security Architect | E34: P1 - Critical | F34: Not Started | G34: 0 | H34: 2025-03-24 | I34: 2025-04-07 | J34: Task 29 | N34: Enable Fusion, anomaly rules; custom KQL rules for AKS
A35: 31 | B35: Security | C35: Sentinel — Playbooks (Logic Apps) for auto-remediation | D35: Security Architect | E35: P2 - High | F35: Not Started | G35: 0 | H35: 2025-04-07 | I35: 2025-04-18 | J35: Task 30 | N35: Auto-close low severity; notify on P1 incidents
A36: 32 | B36: Security | C36: Vulnerability management — Defender CSPM remediation | D36: Security Architect | E36: P2 - High | F36: Not Started | G36: 0 | H36: 2025-03-24 | I36: 2025-04-18 | J36: Tasks 27,28 | N36: Prioritise critical/high findings pre-go-live
A37: 33 | C37: Secret rotation policy — Key Vault certs and secrets | D37: Security Architect | F37: Not Started | G37: 0 | I37: 2025-03-28 | J37: Task 9 | N37: Auto-rotation; alert on expiry < 30 days
A38: 34 | B38: Security | C38: DDoS Protection Standard — on hub VNet | D38: Security Architect | E38: P2 - High | F38: Not Started | G38: 0 | H38: 2025-03-08 | I38: 2025-03-15 | J38: Task 5 | N38: Enable on hub VNet; configure alerts
A39: 35 | B39: Security | C39: Privileged Identity Management (PIM) — JIT access | D39: Security Architect | E39: P1 - Critical | F39: Not Started | G39: 0 | H39: 2025-03-15 | I39: 2025-03-28 | J39: Task 25 | N39: No standing privileged access; require justification
A40: 36 | B40: Operationalisation | C40: Azure Monitor — Log Analytics workspace setup | D40: Cloud Engineer | E40: P2 - High | F40: Not Started | G40: 0 | H40: 2025-03-10 | I40: 2025-03-17 | N40: Centralised workspace; 90-day retention minimum
A41: 37 | B41: Operationalisation | C41: Diagnostic settings — all resources to Log Analytics | D41: Cloud Engineer | E41: P2 - High | F41: Not Started | G41: 0 | H41: 2025-03-17 | I41: 2025-03-24 | J41: Task 36 | N41: AKS, Firewall, Key Vault, Service Bus, ACR
...

Sheet Risk Register
A1: Risk Register
A3: Risk ID | B3: Phase | C3: Risk Description | D3: Likelihood | E3: Impact | F3: Risk Score | G3: Mitigation | H3: Owner | I3: Status | J3: Notes
A4: R001 | B4: Build | C4: Lambda not triggered by Health events | D4: Medium | E4: High | F4: =D4*E4 -> #VALUE! | G4: Update EventBridge pattern | H4: TBD | I4: Open
A5: R002 | B5: Security | C5: Overprivileged IAM roles | D5: Low | E5: High | F5: =D5*E5 -> #VALUE! | G5: Enforce least privilege | H5: TBD | I5: Open
A6: R003 | B6: Compliance | C6: Protected B controls not met | D6: Medium | E6: High | F6: =D6*E6 -> #VALUE! | G6: Map all controls before deployment | H6: TBD | I6: Open
A7: R004 | B7: Application | C7: Multi-account deployment failure | D7: Medium | E7: High | F7: =D7*E7 -> #VALUE! | G7: Test in non-prod first | H7: TBD | I7: Open
A8: R005 | B8: Operationalisation | C8: No alerting on Lambda failures | D8: High | E8: High | F8: =D8*E8 -> #VALUE! | G8: DLQ + CloudWatch alarm | H8: TBD | I8: Open
A9: R006 | B9: Documentation | C9: Runbooks not maintained | D9: Medium | E9: Medium | F9: =D9*E9 -> #VALUE! | G9: Assign doc owner per phase | H9: TBD | I9: Open

Sheet Control List
A1: Control List — Protected B & AWS Security Controls
A3: Control ID | B3: Category | C3: Control Description | D3: Phase | E3: Owner | F3: Implementation Status | G3: Evidence Required | H3: Due Date | I3: Notes
A4: C001 | B4: Access Control | C4: Least privilege IAM roles | D4: Security | E4: TBD | F4: Not Started | G4: IAM policy JSON
A5: C002 | B5: Access Control | C5: MFA enforced on all accounts | D5: Security | E5: TBD | F5: Not Started | G5: IAM report
A6: C003 | B6: Audit & Logging | C6: CloudTrail enabled all regions | D6: Compliance | E6: TBD | F6: Not Started | G6: CloudTrail config
A7: C004 | B7: Audit & Logging | C7: CloudWatch log retention >= 90 days | D7: Compliance | E7: TBD | F7: Not Started | G7: Log group config
A8: C005 | B8: Data Protection | C8: KMS encryption for SNS topics | D8: Security | E8: TBD | F8: Not Started | G8: KMS key policy
A9: C006 | B9: Data Protection | C9: SES TLS enforced | D9: Build | E9: TBD | F9: Not Started | G9: SES config
A10: C007 | B10: Incident Response | C10: DLQ configured on Lambda | D10: Operationalisation | E10: TBD | F10: Not Started | G10: Lambda config
A11: C008 | B11: Incident Response | C11: Runbook documented and tested | D11: Operationalisation | E11: TBD | F11: Not Started | G11: Runbook doc
A12: C009 | B12: Vulnerability Mgmt | C12: Lambda code scanning in CI/CD | D12: Application | E12: TBD | F12: Not Started | G12: CI/CD pipeline
A13: C010 | B13: Compliance | C13: Protected B data classification | D13: Compliance | E13: TBD | F13: Not Started | G13: Classification doc
A14: C011 | B14: Network | C14: VPC endpoints where applicable | D14: Security | E14: TBD | F14: Not Started | G14: VPC config
A15: C012 | B15: Change Mgmt | C15: All changes via approved pipeline | D15: Application | E15: TBD | F15: Not Started | G15: Pipeline config

Sheet Resources and Personnel
A1: Resources and Personnel
A3: Name | B3: Role | C3: Team | D3: Phase Ownership | E3: AWS Account Access | F3: Availability | G3: Contact | H3: Notes
A4: TBD | B4: Project Lead | C4: Cloud Ops | D4: All Phases | E4: Prod / Non-Prod / Dev | F4: Full-time
A5: TBD | B5: Cloud Engineer | C5: Infrastructure | D5: Build, Application | E5: Prod / Non-Prod | F5: Full-time
A6: TBD | B6: Security Architect | C6: Security | D6: Security, Compliance | E6: Non-Prod | F6: Part-time
A7: TBD | B7: Compliance Officer | C7: Risk & Compliance | D7: Compliance | E7: Read-only | F7: Part-time
A8: TBD | B8: Developer | C8: Application | D8: Application | E8: Non-Prod / Dev | F8: Full-time
A9: TBD | B9: Technical Writer | C9: Documentation | D9: Documentation | E9: Read-only | F9: Part-time

Sheet RACI Matrix
A1: RACI Matrix
J2: RACI LEGEND
A3: Activity / Phase | B3: Project Lead | C3: Cloud Engineer | D3: Security Architect | E3: Compliance Officer | F3: Developer | G3: Tech Writer | K3: R — Responsible
A4: Build — Lambda Development | B4: A | C4: R | D4: C | E4: I | F4: R | G4: I | K4: A — Accountable
A5: Build — EventBridge Setup | B5: A | C5: R | D5: C | E5: I | F5: C | G5: I | K5: C — Consulted
A6: Application — IaC Templates | B6: A | C6: R | D6: I | E6: I | F6: R | G6: I | K6: I — Informed
A7: Application — CI/CD Pipeline | B7: A | C7: C | D7: I | E7: I | F7: R | G7: I
A8: Security — IAM Review | B8: C | C8: C | D8: R | E8: I | F8: I | G8: I
A9: Security — Threat Model | B9: A | C9: C | D9: R | E9: C | F9: I | G9: I
A10: Operationalisation — Runbooks | B10: A | C10: R | D10: C | E10: C | F10: C | G10: R
A11: Operationalisation — Monitoring | B11: A | C11: R | D11: C | E11: I | F11: R | G11: I
A12: Compliance — Control Mapping | B12: C | C12: I | D12: C | E12: R | F12: I | G12: I
A13: Compliance — Audit Evidence | B13: A | C13: C | D13: C | E13: R | F13: I | G13: I
A14: Documentation — Build Docs | B14: A | C14: R | D14: C | E14: I | F14: R | G14: R
A15: Documentation — Ops Runbooks | B15: A | C15: R | D15: C | E15: C | F15: C | G15: R

Sheet Stack
A1: Technology Stack — AWS Health Notification Solution
A3: Component | B3: Service / Tool | C3: Type | D3: Purpose | E3: Phase | F3: Account Scope | G3: Version / Config | H3: Notes
A4: Kubernetes | B4: Azure Kubernetes Service (AKS) | C4: Azure PaaS | D4: Run containerised workloads | E4: Build | F4: All envs | G4: 1.29+; private cluster | H4: System + user node pools
A5: Container Registry | B5: Azure Container Registry (ACR) | C5: Azure PaaS | D5: Store and scan container images | E5: Build | F5: All envs | G5: Premium; geo-replicated | H5: Private endpoint; image scanning
A6: CI/CD | B6: Azure DevOps Pipelines | C6: Azure DevOps | D6: Build, test, deploy automation | E6: Application | F6: All envs | G6: YAML pipelines | H6: Self-hosted agents on AKS
A7: IaC | B7: Terraform | C7: OSS Tool | D7: Provision all Azure infrastructure | E7: Build | F7: All envs | G7: AzureRM provider | H7: State in Azure Storage
A8: Networking | B8: Azure Virtual Network (VNet) | C8: Azure PaaS | D8: Hub-spoke network topology | E8: Build | F8: All envs | G8: Hub-spoke | H8: Dedicated AKS subnet
A9: Firewall | B9: Azure Firewall | C9: Azure PaaS | D9: Centralised egress and ingress control | E9: Build | F9: Hub VNet | G9: Premium SKU | H9: IDPS enabled; TLS inspection
A10: Network Security | B10: Network Security Groups (NSGs) | C10: Azure PaaS | D10: Subnet-level traffic filtering | E10: Build | F10: All envs | G10: Flow logs enabled | H10: Deny-all default rules
A11: Private Access | B11: Private Endpoints | C11: Azure PaaS | D11: Private connectivity to PaaS services | E11: Build | F11: All envs | G11: Per service | H11: ACR, KV, Service Bus, Storage
A12: Secrets | B12: Azure Key Vault | C12: Azure PaaS | D12: Secrets, certs, encryption keys | E12: Build | F12: All envs | G12: RBAC auth mode | H12: Soft-delete + purge protection
A13: Messaging | B13: Azure Service Bus | C13: Azure PaaS | D13: Health event routing and fan-out | E13: Build | F13: All envs | G13: Premium; VNet integrated | H13: Dead-letter queue enabled
A14: Identity | B14: Microsoft Entra ID (Azure AD) | C14: Azure PaaS | D14: IAM, RBAC, MFA, Conditional Access | E14: Security | F14: Tenant-wide | G14: P2 licence | H14: PIM for privileged roles
... A20: APM | B20: Application Insights | C20: Azure PaaS | D20: Application performance monitoring | E20: Operationalisation | F20: All envs | G20: SDK / auto-instrument | H20: Connected to Log Analytics WS
A21: DDoS | B21: Azure DDoS Protection | C21: Azure PaaS | D21: DDoS mitigation on public IPs | E21: Security | F21: Hub VNet | G21: Standard plan
A22: Policy | B22: Azure Policy | C22: Azure PaaS | D22: Enforce compliance and governance | E22: Compliance | F22: Management group | G22: Built-in + custom initiatives | H22: CIS, NIST, Protected B
A23: Ingress | B23: Azure Application Gateway + WAF | C23: Azure PaaS | D23: L7 load balancing and WAF | E23: Application | F23: All envs | G23: WAF v2; prevention mode | H23: Attached to AKS ingress

Sheet Documentation
A1: Documentation Index
A3: Doc ID | B3: Phase | C3: Document Name | D3: Type | E3: Owner | F3: Status | G3: Location / Link | H3: Last Updated | I3: Notes
A4: D001 | B4: Build | C4: Lambda Architecture — Build Doc | D4: Build Doc | E4: TBD | F4: Not Started | G4: TBD
A5: D002 | B5: Build | C5: EventBridge Rule Configuration — Build Doc | D5: Build Doc | E5: TBD | F5: Not Started | G5: TBD
A6: D003 | B6: Build | C6: SES Domain Setup — Build Doc | D6: Build Doc | E6: TBD | F6: Not Started | G6: TBD
A7: D004 | B7: Application | C7: IaC Template Reference — Build Doc | D7: Build Doc | E7: TBD | F7: Not Started | G7: TBD
A8: D005 | B8: Application | C8: CI/CD Pipeline — Build Doc | D8: Build Doc | E8: TBD | F8: Not Started | G8: TBD
A9: D006 | B9: Security | C9: IAM Role Design — Build Doc | D9: Build Doc | E9: TBD | F9: Not Started | G9: TBD
A10: D007 | B10: Security | C10: Threat Model Document | D10: Security Doc | E10: TBD | F10: Not Started | G10: TBD
A11: D008 | B11: Operationalisation | C11: Incident Response Runbook | D11: Ops Runbook | E11: TBD | F11: Not Started | G11: TBD
A12: D009 | B12: Operationalisation | C12: Email Delivery Failure Runbook | D12: Ops Runbook | E12: TBD | F12: Not Started | G12: TBD
A13: D010 | B13: Operationalisation | C13: Resubscribe Email Addresses Runbook | D13: Ops Runbook | E13: TBD | F13: Not Started | G13: TBD
A14: D011 | B14: Compliance | C14: Protected B Control Mapping | D14: Compliance Doc | E14: TBD | F14: Not Started | G14: TBD
A15: D012 | B15: Compliance | C15: Audit Evidence Package | D15: Compliance Doc | E15: TBD | F15: Not Started | G15: TBD
... A17: D014 | B17: Documentation | C17: Architecture Overview Diagram | D17: Diagram | E17: TBD | F17: Not Started | G17: TBD

Sheet Change Log
A1: Change Log
A3: Change ID | B3: Date | C3: Changed By | D3: Phase | E3: Description of Change | F3: Approved By | G3: Notes
A4: CHG001 | B4: 2026-03-06 | C4: Project Lead | D4: All | E4: Initial project tracker created | F4: TBD
